Workbook

Sheet Trial 1
A1: Spine ID | B1: Spine Intensity | C1: Dendrite Intensity | D1: Volume | F1: Spine | H1: Dendrite
A2: 19 | B2: 591.359 | C2: 628.461 | D2: =B2/C2 -> 0.94096372 | F2: ="x" -> x | G2: ="x" -> x | H2: ="x" -> x | I2: ="x" -> x
A3: 4 | B3: 489.152 | C3: 664.085 | D3: =B3/C3 -> 0.73658041 | F3: ="x" -> x | G3: ="x" -> x | H3: ="x" -> x | I3: ="x" -> x
A4: 21 | B4: 479.297 | C4: 569.37 | D4: =B4/C4 -> 0.84180234 | F4: ="x" -> x | G4: ="x" -> x | H4: ="x" -> x | I4: ="x" -> x
A5: 22 | B5: 364.637 | C5: 548.363 | D5: =B5/C5 -> 0.66495551 | F5: ="x" -> x | G5: ="x" -> x | H5: ="x" -> x | I5: ="x" -> x
A6: 3 | B6: =G6 -> 730.93 | C6: =I6 -> 783 | D6: =B6/C6 -> 0.93349936 | F6: 22 | G6: 730.93 | H6: 34 | I6: 783
A7: 23 | B7: =G7 -> 460.692 | C7: =I7 -> 792.569 | D7: =B7/C7 -> 0.58126422 | F7: 20 | G7: 460.692 | H7: 34 | I7: 792.569
A8: 5 | B8: =G8 -> 450.153 | C8: =I8 -> 737.978 | D8: =B8/C8 -> 0.6099816 | F8: 36 | G8: 450.153 | H8: 50 | I8: 737.978
A9: 9 | B9: =G9 -> 688.14 | C9: =I9 -> 799.612 | D9: =B9/C9 -> 0.86059239 | F9: 32 | G9: 688.14 | H9: 50 | I9: 799.612
A10: 30 | B10: =G10 -> 310.803 | C10: =I10 -> 720.047 | D10: =B10/C10 -> 0.43164266 | F10: 13 | G10: 310.803 | H10: 25 | I10: 720.047
A11: 10 | B11: =G11 -> 829.915 | C11: =I11 -> 825.5 | D11: =B11/C11 -> 1.0053483 | F11: 30 | G11: 829.915 | H11: 43 | I11: 825.5
A12: 24 | B12: =G12 -> 257.275 | C12: =I12 -> 726.015 | D12: =B12/C12 -> 0.35436596 | F12: 46 | G12: 257.275 | H12: 61 | I12: 726.015
A13: 8 | B13: =G13 -> 485.429 | C13: =I13 -> 617.295 | D13: =B13/C13 -> 0.7863809 | F13: 22 | G13: 485.429 | H13: 46 | I13: 617.295
A14: 28 | B14: =G14 -> 833.838 | C14: =I14 -> 639.69 | D14: =B14/C14 -> 1.3035033 | F14: 31 | G14: 833.838 | H14: 43 | I14: 639.69
A15: 27 | B15: =G15 -> 833.838 | C15: =I15 -> 639.69 | D15: =B15/C15 -> 1.3035033 | F15: 31 | G15: 833.838 | H15: 43 | I15: 639.69
A16: 38 | B16: =G16 -> 400.482 | C16: =I16 -> 624.497 | D16: =B16/C16 -> 0.64128731 | F16: 15 | G16: 400.482 | H16: 25 | I16: 624.497
A17: 31 | B17: =G17 -> 389.755 | C17: =I17 -> 709.219 | D17: =B17/C17 -> 0.54955521 | F17: 15 | G17: 389.755 | H17: 28 | I17: 709.219
... A21: 17 | B21: =G21 -> 511.325 | C21: =I21 -> 899.526 | D21: =B21/C21 -> 0.56843827 | F21: 13 | G21: 511.325 | H21: 29 | I21: 899.526
A22: 16 | B22: =G22 -> 493.637 | C22: =I22 -> 823.191 | D22: =B22/C23 -> 0.66459915 | F22: 24 | G22: 493.637 | H22: 32 | I22: 823.191
A23: 42 | B23: =G23 -> 502.099 | C23: =I23 -> 742.759 | D23: =B23/C23 -> 0.67599181 | F23: 10 | G23: 502.099 | H23: 16 | I23: 742.759

Sheet Trial 2
A1: Spine ID | B1: Spine Intensity | C1: Dendrite Intensity | D1: Volume | F1: Spine | H1: Dendrite
A2: 19 | B2: =G2 -> 589.419 | C2: =I2 -> 777.983 | D2: =B2/C2 -> 0.75762452 | F2: 1.296 | G2: 589.419 | H2: 4.428 | I2: 777.983
A3: 4 | B3: =G3 -> 492.968 | C3: =I3 -> 680.05 | D3: =B3/C3 -> 0.72489964 | F3: 1.836 | G3: 492.968 | H3: 2.916 | I3: 680.05
A4: 21 | B4: =G4 -> 478.163 | C4: =I4 -> 562.885 | D4: =B4/C4 -> 0.84948613 | F4: 1.944 | G4: 478.163 | H4: 3.456 | I4: 562.885
A5: 22 | B5: =G5 -> 373.217 | C5: =I5 -> 700.767 | D5: =B5/C5 -> 0.53258358 | F5: 2.052 | G5: 373.217 | H5: 4.428 | I5: 700.767
A6: 3 | B6: =G6 -> 751.719 | C6: =I6 -> 754.733 | D6: =B6/C6 -> 0.99600653 | F6: 2.268 | G6: 751.719 | H6: 3.672 | I6: 754.733
A7: 23 | B7: =G7 -> 458.308 | C7: =I7 -> 796.98 | D7: =B7/C7 -> 0.57505584 | F7: 1.404 | G7: 458.308 | H7: 2.916 | I7: 796.98
A8: 5 | B8: =G8 -> 453.143 | C8: =I8 -> 753.637 | D8: =B8/C8 -> 0.60127488 | F8: 1.728 | G8: 453.143 | H8: 3.24 | I8: 753.637
A9: 9 | B9: =G9 -> 661.428 | C9: =I9 -> 856.193 | D9: =B9/C9 -> 0.77252208 | F9: 2.376 | G9: 661.428 | H9: 4.536 | I9: 856.193
A10: 30 | B10: =G10 -> 318.135 | C10: =I10 -> 724.047 | D10: =B10/C10 -> 0.43938446 | F10: 0.864 | G10: 318.135 | H10: 2.052 | I10: 724.047
A11: 10 | B11: =G11 -> 830.954 | C11: =I11 -> 830.885 | D11: =B11/C11 -> 1.000083 | F11: 2.268 | G11: 830.954 | H11: 3.564 | I11: 830.885
A12: 24 | B12: =G12 -> 266.629 | C12: =I12 -> 739.875 | D12: =B12/C12 -> 0.36037033 | F12: 1.188 | G12: 266.629 | H12: 2.916 | I12: 739.875
A13: 8 | B13: =G13 -> 499.253 | C13: =I13 -> 632.321 | D13: =B13/C13 -> 0.78955625 | F13: 2.484 | G13: 499.253 | H13: 5.616 | I13: 632.321
... A22: 16 | B22: =G22 -> 528.05 | C22: =I22 -> 823.866 | D22: =B22/C22 -> 0.64094161 | F22: 1.512 | G22: 528.05 | H22: 2.376 | I22: 823.866
A23: 42 | B23: =G23 -> 0 | C23: =I23 -> 0 | D23: =B23/C23 -> #DIV/0!

Sheet Trial 3
A1: Spine ID | B1: Spine Intensity | C1: Dendrite Intensity | D1: Volume | F1: Spine | H1: Dendrite
A2: 19 | B2: =G2 -> 542.083 | C2: =I2 -> 783.022 | D2: =B2/C2 -> 0.692296 | F2: 0.972 | G2: 542.083 | H2: 4.212 | I2: 783.022
A3: 4 | B3: =G3 -> 495.753 | C3: =I3 -> 715.551 | D3: =B3/C3 -> 0.69282693 | F3: 1.836 | G3: 495.753 | H3: 3.24 | I3: 715.551
A4: 21 | B4: =G4 -> 469.946 | C4: =I4 -> 564.627 | D4: =B4/C4 -> 0.83231231 | F4: 2.268 | G4: 469.946 | H4: 3.78 | I4: 564.627
A5: 22 | B5: =G5 -> 391.709 | C5: =I5 -> 562.098 | D5: =B5/C5 -> 0.69686959 | F5: 1.296 | G5: 391.709 | H5: 3.78 | I5: 562.098
A6: 3 | B6: =G6 -> 715.897 | C6: =I6 -> 821.817 | D6: =B6/C6 -> 0.87111486 | F6: 1.944 | G6: 715.897 | H6: 3.24 | I6: 821.817
A7: 23 | B7: =G7 -> 451.692 | C7: =I7 -> 784.7 | D7: =B7/C7 -> 0.57562381 | F7: 1.512 | G7: 451.692 | H7: 2.916 | I7: 784.7
A8: 5 | B8: =G8 -> 438.095 | C8: =I8 -> 744.379 | D8: =B8/C8 -> 0.58853756 | F8: 0.972 | G8: 438.095 | H8: 2.592 | I8: 744.379
A9: 9 | B9: =G9 -> 629.803 | C9: =I9 -> 852.258 | D9: =B9/C9 -> 0.73898162 | F9: 1.728 | G9: 629.803 | H9: 4.212 | I9: 852.258
A10: 30 | B10: =G10 -> 322.191 | C10: =I10 -> 778.011 | D10: =B10/C10 -> 0.41412139 | F10: 0.756 | G10: 322.191 | H10: 2.16 | I10: 778.011
A11: 10 | B11: =G11 -> 822.638 | C11: =I11 -> 808.507 | D11: =B11/C11 -> 1.0174779 | F11: 3.132 | G11: 822.638 | H11: 4.536 | I11: 808.507
A12: 24 | B12: =G12 -> 266.897 | C12: =I12 -> 720.458 | D12: =B12/C12 -> 0.37045463 | F12: 1.188 | G12: 266.897 | H12: 2.808 | I12: 720.458
A13: 8 | B13: =G13 -> 456.812 | C13: =I13 -> 620.357 | D13: =B13/C13 -> 0.73636954 | F13: 1.728 | G13: 456.812 | H13: 4.86 | I13: 620.357
... A23: 42 | B23: =G23 -> 0 | C23: =I23 -> 0 | D23: =B23/C23 -> #DIV/0! | F23: 0 | G23: 0 | H23: 0 | I23: 0

Sheet Sheet1
A1: Spine ID | B1: Trial 1 | C1: Trial 2 | D1: Trial 3 | E1: Avg | F1: Respan value | H1: All trials | I1: Avg | L1: Avg | M1: Respan
A2: 19 | B2: {='Trial 1'!D2:D23} -> 0.94096372 | C2: {='Trial 2'!D2:D23} -> 0.75762452 | D2: ='Trial 3'!D2 -> 0.692296 | E2: =AVERAGE(B2:D2) -> 0.79696142 | F2: 0.180792 | H2: {=B2:B14} -> 0.94096372 | I2: {=E2:E14} -> 0.79696142 | L2: =AVERAGE(I2:K2) -> 0.79696142 | M2: 0.180792
A3: 4 | B3: 0.73658041 | C3: 0.72489964 | D3: ='Trial 3'!D3 -> 0.69282693 | E3: =AVERAGE(B3:D3) -> 0.71810232 | F3: 0.145071 | H3: 0.73658041 | I3: 0.71810232 | L3: =AVERAGE(I3:K3) -> 0.71810232 | M3: 0.145071
A4: 21 | B4: 0.84180234 | C4: 0.84948613 | D4: ='Trial 3'!D4 -> 0.83231231 | E4: =AVERAGE(B4:D4) -> 0.84120026 | F4: 0.237654 | H4: 0.84180234 | I4: 0.84120026 | L4: =AVERAGE(I4:K4) -> 0.84120026 | M4: 0.237654
A5: 22 | B5: 0.66495551 | C5: 0.53258358 | D5: ='Trial 3'!D5 -> 0.69686959 | E5: =AVERAGE(B5:D5) -> 0.63146956 | F5: 0.134136 | H5: 0.66495551 | I5: 0.63146956 | L5: =AVERAGE(I5:K5) -> 0.63146956 | M5: 0.134136
A6: 3 | B6: 0.93349936 | C6: 0.99600653 | D6: ='Trial 3'!D6 -> 0.87111486 | E6: =AVERAGE(B6:D6) -> 0.93354025 | F6: 0.902648 | H6: 0.93349936 | I6: 0.93354025 | L6: =AVERAGE(I6:K6) -> 0.93354025 | M6: 0.902648
A7: 23 | B7: 0.58126422 | C7: 0.57505584 | D7: ='Trial 3'!D7 -> 0.57562381 | E7: =AVERAGE(B7:D7) -> 0.57731462 | F7: 0.149591 | H7: 0.58126422 | I7: 0.57731462 | L7: =AVERAGE(I7:K7) -> 0.57731462 | M7: 0.149591
A8: 5 | B8: 0.6099816 | C8: 0.60127488 | D8: ='Trial 3'!D8 -> 0.58853756 | E8: =AVERAGE(B8:D8) -> 0.59993135 | F8: 0.194497 | H8: 0.6099816 | I8: 0.59993135 | L8: =AVERAGE(I8:K8) -> 0.59993135 | M8: 0.194497
A9: 9 | B9: 0.86059239 | C9: 0.77252208 | D9: ='Trial 3'!D9 -> 0.73898162 | E9: =AVERAGE(B9:D9) -> 0.7906987 | F9: 0.763555 | H9: 0.86059239 | I9: 0.7906987 | L9: =AVERAGE(I9:K9) -> 0.7906987 | M9: 0.763555
A10: 30 | B10: 0.43164266 | C10: 0.43938446 | D10: ='Trial 3'!D10 -> 0.41412139 | E10: =AVERAGE(B10:D10) -> 0.42838284 | F10: 0.022599 | H10: 0.43164266 | I10: 0.42838284 | L10: =AVERAGE(I10:K10) -> 0.42838284 | M10: 0.022599
A11: 10 | B11: 1.0053483 | C11: 1.000083 | D11: ='Trial 3'!D11 -> 1.0174779 | E11: =AVERAGE(B11:D11) -> 1.0076364 | F11: 0.60055 | H11: 1.0053483 | I11: 1.0076364 | L11: =AVERAGE(I11:K11) -> 1.0076364 | M11: 0.60055
A12: 24 | B12: 0.35436596 | C12: 0.36037033 | D12: ='Trial 3'!D12 -> 0.37045463 | E12: =AVERAGE(B12:D12) -> 0.36173031 | F12: 0.063423 | H12: 0.35436596 | I12: 0.36173031 | L12: =AVERAGE(I12:K12) -> 0.36173031 | M12: 0.063423
A13: 8 | B13: 0.7863809 | C13: 0.78955625 | D13: ='Trial 3'!D13 -> 0.73636954 | E13: =AVERAGE(B13:D13) -> 0.7707689 | F13: 0.340006 | H13: 0.7863809 | I13: 0.7707689 | L13: =AVERAGE(I13:K13) -> 0.7707689 | M13: 0.340006
A14: 28 | B14: 1.3035033 | C14: 1.2052753 | D14: ='Trial 3'!D14 -> 1.3167704 | E14: =AVERAGE(B14:D14) -> 1.275183 | F14: 0.039074 | H14: 1.3035033 | I14: 1.275183 | L14: =AVERAGE(I14:K14) -> 1.275183 | M14: 0.039074
A15: 27 | B15: 1.3035033 | C15: 1.2052753 | D15: ='Trial 3'!D15 -> 1.3167704 | E15: =AVERAGE(B15:D15) -> 1.275183 | F15: 0.060361 | H15: {=B16:B22} -> 0.64128731 | I15: {=E16:E22} -> 0.60019726 | L15: =AVERAGE(I15:K15) -> 0.60019726 | M15: 0.062402
A16: 38 | B16: 0.64128731 | C16: 0.5874686 | D16: ='Trial 3'!D16 -> 0.57183587 | E16: =AVERAGE(B16:D16) -> 0.60019726 | F16: 0.062402 | H16: 0.54955521 | I16: 0.56290896 | L16: =AVERAGE(I16:K16) -> 0.56290896 | M16: 0.033097
A17: 31 | B17: 0.54955521 | C17: 0.56407684 | D17: ='Trial 3'!D17 -> 0.57509481 | E17: =AVERAGE(B17:D17) -> 0.56290896 | F17: 0.033097 | H17: 0.786326 | I17: 0.71439577 | L17: =AVERAGE(I17:K17) -> 0.71439577 | M17: 0.074941
A18: 32 | B18: 0.786326 | C18: 0.66358808 | D18: ='Trial 3'!D18 -> 0.69327322 | E18: =AVERAGE(B18:D18) -> 0.71439577 | F18: 0.074941 | H18: 5.7820084 | I18: 4.9676092 | L18: =AVERAGE(I18:K18) -> 4.9676092 | M18: 0.044761
A19: 14 | B19: 5.7820084 | C19: 4.4605547 | D19: ='Trial 3'!D19 -> 4.6602645 | E19: =AVERAGE(B19:D19) -> 4.9676092 | F19: 0.044761 | H19: 0.77463496 | I19: 0.75367795 | L19: =AVERAGE(I19:K19) -> 0.75367795 | M19: 0.120868
A20: 39 | B20: 0.77463496 | C20: 0.73515128 | D20: ='Trial 3'!D20 -> 0.75124761 | E20: =AVERAGE(B20:D20) -> 0.75367795 | F20: 0.120868 | H20: 0.56843827 | I20: 0.63080429 | L20: =AVERAGE(I20:K20) -> 0.63080429 | M20: 0.25238
A21: 17 | B21: 0.56843827 | C21: 0.68194102 | D21: ='Trial 3'!D21 -> 0.64203359 | E21: =AVERAGE(B21:D21) -> 0.63080429 | F21: 0.25238 | H21: 0.66459915 | I21: 0.64138305 | L21: =AVERAGE(I21:K21) -> 0.64138305 | M21: 0.098561
A22: 16 | B22: 0.66459915 | C22: 0.64094161 | D22: ='Trial 3'!D22 -> 0.61860839 | E22: =AVERAGE(B22:D22) -> 0.64138305 | F22: 0.098561 | H22: {=C2:C14} -> 0.75762452 | I22: {=E2:E14} -> 0.79696142
A23: 42 | B23: 0.67599181 | C23: #DIV/0! | D23: ='Trial 3'!D23 -> #DIV/0! | F23: 0.048114 | H23: 0.72489964 | I23: 0.71810232
H24: 0.84948613 | I24: 0.84120026
H25: 0.53258358 | I25: 0.63146956 | L25: =PEARSON(L2:L21,M2:M21) -> -0.081011573
H26: 0.99600653 | I26: 0.93354025
H27: 0.57505584 | I27: 0.57731462
H28: 0.60127488 | I28: 0.59993135
H29: 0.77252208 | I29: 0.7906987
H30: 0.43938446 | I30: 0.42838284
H31: 1.000083 | I31: 1.0076364
H32: 0.36037033 | I32: 0.36173031
H33: 0.78955625 | I33: 0.7707689
H34: 1.2052753 | I34: 1.275183
H35: {=C16:C22} -> 0.5874686 | I35: {=E16:E22} -> 0.60019726
H36: 0.56407684 | I36: 0.56290896
H37: 0.66358808 | I37: 0.71439577
H38: 4.4605547 | I38: 4.9676092
H39: 0.73515128 | I39: 0.75367795
H40: 0.68194102 | I40: 0.63080429
...
